Workbook

Sheet Data
A1: ID | B1: Case_ID | C1: PT | D1: Drug_Name | E1: Q2_Score_NonRAG | F1: Q2_Score_RAG | G1: Q2_Score_Human | H1: Q2_Diff_NonRAG | I1: Q2_Agree_NonRAG | J1: Q2_Over_NonRAG | K1: Q2_Under_NonRAG | L1: Q2_Degree_NonRAG | M1: Q2_Diff_RAG | N1: Q2_Agree_RAG | O1: Q2_Over_RAG | P1: Q2_Under_RAG | Q1: Q2_Degree_RAG | R1: Q5_Score_NonRAG | S1: Q5_Score_RAG | T1: Q5_Score_Human | U1: Q5_Diff_NonRAG | V1: Q5_Agree_NonRAG | W1: Q5_Over_NonRAG | X1: Q5_Under_NonRAG | Y1: Q5_Degree_NonRAG | Z1: Q5_Diff_RAG | AA1: Q5_Agree_RAG | AB1: Q5_Over_RAG | AC1: Q5_Under_RAG | AD1: Q5_Degree_RAG | AE1: Q10_Score_NonRAG | AF1: Q10_Score_RAG | AG1: Q10_Score_Human | AH1: Q10_Diff_NonRAG | AI1: Q10_Agree_NonRAG | AJ1: Q10_Over_NonRAG | AK1: Q10_Under_NonRAG | AL1: Q10_Degree_NonRAG | AM1: Q10_Diff_RAG | AN1: Q10_Agree_RAG | AO1: Q10_Over_RAG | AP1: Q10_Under_RAG | AQ1: Q10_Degree_RAG | AR1: Q2_Reasoning_NonRAG | AS1: Q2_Reasoning_RAG | AT1: Q2_Reasoning_Human | AU1: Q5_Reasoning_NonRAG | AV1: Q5_Reasoning_RAG | AW1: Q5_Reasoning_Human | AX1: Q10_Reasoning_NonRAG | AY1: Q10_Reasoning_RAG | AZ1: Q10_Reasoning_Human | BA1: Case_Narrative
A2: 1 | B2: 153433253 | C2: Intentional product use issue | D2: DIAZEPAM | E2: 0 | F2: 0 | G2: 0 | H2: =E2-G2 -> 0 | I2: =IF(E2=G2,1,0) -> 1 | J2: =IF(E2>G2,1,0) -> 0 | K2: =IF(E2<G2,1,0) -> 0 | L2: =IF(E2=G2,"Agreement",IF(E2>G2,"Overestimation","Underestimation")) -> Agreement | M2: =F2-G2 -> 0 | N2: =IF(F2=G2,1,0) -> 1 | O2: =IF(F2>G2,1,0) -> 0 | P2: =IF(F2<G2,1,0) -> 0 | Q2: =IF(F2=G2,"Agreement",IF(F2>G2,"Overestimation","Underestimation")) -> Agreement | R2: -1 | S2: -1 | T2: 2 | U2: =R2-T2 -> -3 | V2: =IF(R2=T2,1,0) -> 0 | W2: =IF(R2>T2,1,0) -> 0 | X2: =IF(R2<T2,1,0) -> 1 | Y2: =IF(R2=T2,"Agreement",IF(R2>T2,"Overestimation","Underestimation")) -> Underestimation | Z2: =S2-T2 -> -3 | AA2: =IF(S2=T2,1,0) -> 0 | AB2: =IF(S2>T2,1,0) -> 0 | AC2: =IF(S2<T2,1,0) -> 1 | AD2: =IF(S2=T2,"Agreement",IF(S2>T2,"Overestimation","Underestimation")) -> Underestimation | AE2: 0 | AF2: 1 | AG2: 1 | AH2: =AE2-AG2 -> -1 | AI2: =IF(AE2=AG2,1,0) -> 0 | AJ2: =IF(AE2>AG2,1,0) -> 0 | AK2: =IF(AE2<AG2,1,0) -> 1 | AL2: =IF(AE2=AG2,"Agreement",IF(AE2>AG2,"Overestimation","Underestimation")) -> Underestimation | AM2: =AF2-AG2 -> 0 | AN2: =IF(AF2=AG2,1,0) -> 1 | AO2: =IF(AF2>AG2,1,0) -> 0 | AP2: =IF(AF2<AG2,1,0) -> 0 | AQ2: =IF(AF2=AG2,"Agreement",IF(AF2>AG2,"Overestimation","Underestimation")) -> Agreement | AR2: the case does not provide any infomation on therapy start and end date or on the event date, thus temporal and biological plausability can not be established. | AS2: the case does not provide any infomation on therapy start and end date or on the event date, thus temporal and biological plausability can not be established. | AT2: the case does not provide any infomation on therapy start and end date or on the event date, thus temporal and biological plausability can not be established. | AU2: ## Pair Assessment: DIAZEPAM vs Intentional product use issue **CrewAI Final Output:** ``` **Comprehensive Causality Assessment for Intentional product use issue Associated with DIAZEPAM** **FINAL PLAUSIBILITY RATING:** HIGH **Detailed Causality Analysis:** **1. Temporal Plausibility** The temporal relationship between DIAZEPAM administration and the onset of the 'Intentional product use issue' is difficult to assess due to missing data. The patient's therapy with DIAZEPAM began on 22-May-2018, but the date of the event is reported as MISSING. For causality to be established, the event must have occurred on or after the start date. Events like misuse or dependence often develop over a period of exposure rather than as a single acute event. While a definitive temporal link cannot be confirmed from the available data, the exposure to DIAZEPAM precedes or coincides with the event, which is a necessary condition for causality. The lack of a specific event date is a significant limitation but does not rule out a plausible temporal connection. **2. Biological Plausibility** The biological plausibility for DIAZEPAM causing or contributing to an 'Intentional product use issue' is extremely high. As detailed in the provided literature summary, DIAZEPAM is a benzodiazepine that enhances the effect of the inhibitory neurotransmitter GABA at the GABA-A receptor, leading to widespread CNS depression. This mechanism produces the drug's therapeutic anxiolytic and sedative effects, but also underlies its significant potential for misuse, abuse, and dependence. The literature confirms that DIAZEPAM is frequently misused for its euphoric and relaxing effects, to self-medicate anxiety, or in patterns of polysubstance abuse. The development of tolerance and physiological dependence is a well-documented consequence of regular use, which can drive behaviors consistent with an 'Intentional product use issue' (e.g., taking more than prescribed). Therefore, the reported event is entirely consistent with the known pharmacological and clinical profile of DIAZEPAM. **3. Dechallenge/Rechallenge** The dechallenge result for DIAZEPAM is reported as 'U' (Unknown), and the rechallenge result is MISSING. Consequently, no information is available from dechallenge or rechallenge to either support or refute a causal relationship between DIAZEPAM and the 'Intentional product use issue'. This represents a critical gap in the case information. **4. Objective Evidence** The primary evidence is the report of the event itself. A highly significant piece of supporting information is the patient's reported "History of Similar Reactions: Y". This indicates a pre-existing vulnerability or pattern of behavior that makes the occurrence of an 'Intentional product use issue' with a high-risk medication like DIAZEPAM more likely. This history corroborates the plausibility of the reported event. No other objective evidence, such as clinical notes, laboratory results, or diagnostic findings, was provided. **5. Confounding Factors** Several confounding factors are present. The patient has a diagnosis of Immune Thrombocytopenia and was treated with RITUXAN and PREDNISONE. The underlying medical condition and its treatment can cause significant psychological distress. PREDNISONE, a corticosteroid, is well-known for causing neuropsychiatric side effects, including anxiety, mood swings, and agitation, which could influence patient behavior. The listed indication for PREDNISONE is 'Anxiety', which is unusual and may suggest a complex pre-existing psychiatric history or a data entry error. This underlying anxiety could be a primary driver for the patient to misuse an anxiolytic medication like DIAZEPAM. Therefore, the patient's underlying medical and psychiatric state, as well as the effects of concurrent PREDNISONE, are significant confounders. **6. Synthesis and Final Assessment** This case involves a 68-year-old female with a "History of Similar Reactions" who experienced an 'Intentional product use issue' while on DIAZEPAM. The primary strength of this case is the exceptionally high biological plausibility; DIAZEPAM's mechanism of action and extensive clinical history directly support its potential for misuse, abuse, and dependence. This is further strengthened by the patient's specific history of similar events, suggesting a predisposition to this type of adverse event. However, the case is weakened by significant missing information, including the event date, dose, indication for DIAZEPAM, and the outcome of dechallenge. Confounding factors, notably the patient's underlying anxiety and concurrent use of PREDNISONE, are present and could have contributed to the event. Despite these limitations, the nature of the event ('Intentional product use issue') aligns perfectly with the well-established and prominent risk profile of DIAZEPAM. The drug's inherent properties are a more direct and powerful explanation for this specific event than the confounding factors. Therefore, a causal relationship is considered highly probable. **Final Plausibility Rating: HIGH** ``` | AV2: ## Pair Assessment: DIAZEPAM vs Intentional product use issue **CrewAI Final Output:** ``` **Comprehensive Causality Assessment for Intentional product use issue Associated with DIAZEPAM** **FINAL PLAUSIBILITY RATING:** HIGH **Detailed Causality Analysis:** **1. Temporal Plausibility** The temporal relationship between DIAZEPAM administration and the onset of the 'Intentional product use issue' is difficult to assess due to missing data. The patient's therapy with DIAZEPAM began on 22-May-2018, but the date of the event is reported as MISSING. For causality to be established, the event must have occurred on or after the start date. Events like misuse or dependence often develop over a period of exposure rather than as a single acute event. While a definitive temporal link cannot be confirmed from the available data, the exposure to DIAZEPAM precedes or coincides with the event, which is a necessary condition for causality. The lack of a specific event date is a significant limitation but does not rule out a plausible temporal connection. **2. Biological Plausibility** The biological plausibility for DIAZEPAM causing or contributing to an 'Intentional product use issue' is extremely high. As detailed in the provided literature summary, DIAZEPAM is a benzodiazepine that enhances the effect of the inhibitory neurotransmitter GABA at the GABA-A receptor, leading to widespread CNS depression. This mechanism produces the drug's therapeutic anxiolytic and sedative effects, but also underlies its significant potential for misuse, abuse, and dependence. The literature confirms that DIAZEPAM is frequently misused for its euphoric and relaxing effects, to self-medicate anxiety, or in patterns of polysubstance abuse. The development of tolerance and physiological dependence is a well-documented consequence of regular use, which can drive behaviors consistent with an 'Intentional product use issue' (e.g., taking more than prescribed). Therefore, the reported event is entirely consistent with the known pharmacological and clinical profile of DIAZEPAM. **3. Dechallenge/Rechallenge** The dechallenge result for DIAZEPAM is reported as 'U' (Unknown), and the rechallenge result is MISSING. Consequently, no information is available from dechallenge or rechallenge to either support or refute a causal relationship between DIAZEPAM and the 'Intentional product use issue'. This represents a critical gap in the case information. **4. Objective Evidence** The primary evidence is the report of the event itself. A highly significant piece of supporting information is the patient's reported "History of Similar Reactions: Y". This indicates a pre-existing vulnerability or pattern of behavior that makes the occurrence of an 'Intentional product use issue' with a high-risk medication like DIAZEPAM more likely. This history corroborates the plausibility of the reported event. No other objective evidence, such as clinical notes, laboratory results, or diagnostic findings, was provided. **5. Confounding Factors** Several confounding factors are present. The patient has a diagnosis of Immune Thrombocytopenia and was treated with RITUXAN and PREDNISONE. The underlying medical condition and its treatment can cause significant psychological distress. PREDNISONE, a corticosteroid, is well-known for causing neuropsychiatric side effects, including anxiety, mood swings, and agitation, which could influence patient behavior. The listed indication for PREDNISONE is 'Anxiety', which is unusual and may suggest a complex pre-existing psychiatric history or a data entry error. This underlying anxiety could be a primary driver for the patient to misuse an anxiolytic medication like DIAZEPAM. Therefore, the patient's underlying medical and psychiatric state, as well as the effects of concurrent PREDNISONE, are significant confounders. **6. Synthesis and Final Assessment** This case involves a 68-year-old female with a "History of Similar Reactions" who experienced an 'Intentional product use issue' while on DIAZEPAM. The primary strength of this case is the exceptionally high biological plausibility; DIAZEPAM's mechanism of action and extensive clinical history directly support its potential for misuse, abuse, and dependence. This is further strengthened by the patient's specific history of similar events, suggesting a predisposition to this type of adverse event. However, the case is weakened by significant missing information, including the event date, dose, indication for DIAZEPAM, and the outcome of dechallenge. Confounding factors, notably the patient's underlying anxiety and concurrent use of PREDNISONE, are present and could have contributed to the event. Despite these limitations, the nature of the event ('Intentional product use issue') aligns perfectly with the well-established and prominent risk profile of DIAZEPAM. The drug's inherent properties are a more direct and powerful explanation for this specific event than the confounding factors. Therefore, a causal relationship is considered highly probable. **Final Plausibility Rating: HIGH** ``` | AW2: These are not pharmacological adverse reactions but usage/process issues. | AX2: Intentional product use issue: Symptom - Intentional product use issue refers to a patient's deliberate misuse or incorrect use of a product, which is a subjective behavior or action reported by the patient or caregiver, not an objective, measurable clinical finding. | AY2: Intentional product use issue: Sign - Intentional product use issue is an observable behavior or event, not a subjective patient-reported experience. | AZ2: since the intentional use is a clinical sign (as opposed to a symptom), it is assumed that the appropriate medical tests have been performed by a healthcare professional, prior to diagnosing. | BA2: Case ID: 153433253 Case Version: 3 FDA Code: F Event Date: NA Manufacture Date: 20180827 Initial FDA Date: 20180903 FDA Date: 20250430 Report Code: EXP Authorization Number: NA Manufacturer Number: US-ROCHE-2176536 Manufacturer Sender: ROCHE Literature Reference: NA Age: 68 Age Code: YR Age Group: E Sex: F E Sub: Y Weight: 71.73 Weight Code: KG Report Date: 20250430 To Manufacturer: NA Occupation Code: HP Reporter Country: US Occurrence Country: US Adverse Reaction(s): Aortic arteriosclerosis ; Dizziness ; Acute kidney injury ; Intentional product use issue ; Sepsis ; Nausea ; Hallucination ; Hypovolaemia ; Immunosuppression ; Atelectasis ; Serum sickness ; Spinal osteoarthritis ; Renal cyst ; Pyrexia ; Lactic acidosis ; Asthenia ; Off label use ; Pleural effusion ; Dehydration Case ID Number: 15343325 Drug Sequence: 6 ; 3 ; 4 ; 10 ; 7 ; 1 ; 9 ; 5 ; 2 ; 8 Role Code: C ; C ; C ; C ; C ; PS ; C ; C ; SS ; C Drug Name: THYROID ; NEXIUM ; PREDNISONE ; DELTASONE ; BENADRYL ; RITUXAN ; ZOFRAN ; PREDNISONE ; DIAZEPAM ; REGLAN Product AI: THYROID ; NEXIUM ; PREDNISONE ; DELTASONE ; BENADRYL ; RITUXAN ; ZOFRAN ; PREDNISONE ; DIAZEPAM ; REGLAN Val VBM: 1 ; 1 ; 1 ; 1 ; 1 ; 1 ; 1 ; 1 ; 1 ; 1 Route: Oral ; NA ; Oral ; NA ; NA ; Intravenous (not otherwise specified) ; NA ; Oral ; Unknown ; NA Dose VBM: daily ; daily ; 2.5 m/d daily ; 1mg daily or more 90 mg daily ; NA ; NA ; prn ; NA ; NA ; prn Cumulative Dose (Char): NA ; NA ; NA ; NA ; NA ; NA ; NA ; NA ; NA ; NA Cumulative Dose (Unit): NA ; NA ; NA ; NA ; NA ; NA ; NA ; NA ; NA ; NA Dechal: NA ; NA ; NA ; NA ; NA ; U ; NA ; NA ; U ; NA Rechal: NA ; NA ; NA ; NA ; NA ; NA ; NA ; NA ; NA ; NA Lot Number: NA ; NA ; NA ; NA ; NA ; Unknown ; NA ; NA ; Unknown ; NA Expiration Date: NA ; NA ; NA ; NA ; NA ; NA ; NA ; NA ; NA ; NA NDA Number: NA ; NA ; NA ; NA ; NA ; 103705 ; NA ; NA ; NA ; NA Dose Amount: 90 ; 20 ; NA ; NA ; NA ; 690 ; NA ; 1 ; 2 ; 10 Dose Unit: MG ; MG ; NA ; NA ; NA ; MG ; NA ; MG ; MG ; MG Dose Form: NA ; NA ; Tablet ; NA ; NA ; Solution for infusion ; NA ; 10 mg tablet ; NA ; NA Dose Frequency: QD ; QD ; QD ; NA ; NA ; /WK ; NA ; QOD ; NA ; Q6H Indication for Use: Immune thrombocytopenia ; Immune thrombocytopenia ; Anxiety ; Anxiety ; Gastrooesophageal reflux disease ; Immune thrombocytopenia ; Immune thrombocytopenia ; ; ; ; ; ; Therapy Start Date: NA ; NA ; NA ; NA ; NA ; 20180501 ; NA ; NA ; 20180522 ; NA Therapy End Date: NA ; NA ; 20180522 ; NA ; NA ; 20180508 ; NA ; NA ; NA ; NA Duration: NA ; NA ; NA ; NA ; NA ; 8 ; NA ; NA ; NA ; NA Duration Code: NA ; NA ; NA ; NA ; NA ; DAY ; NA ; NA ; NA ; NA
A3: 2 | B3: 153433253 | C3: Intentional product use issue | D3: REGLAN | E3: 0 | F3: 0 | G3: 0 | H3: =E3-G3 -> 0 | I3: =IF(E3=G3,1,0) -> 1 | J3: =IF(E3>G3,1,0) -> 0 | K3: =IF(E3<G3,1,0) -> 0 | L3: =IF(E3=G3,"Agreement",IF(E3>G3,"Overestimation","Underestimation")) -> Agreement | M3: =F3-G3 -> 0 | N3: =IF(F3=G3,1,0) -> 1 | O3: =IF(F3>G3,1,0) -> 0 | P3: =IF(F3<G3,1,0) -> 0 | Q3: =IF(F3=G3,"Agreement",IF(F3>G3,"Overestimation","Underestimation")) -> Agreement | R3: -1 | S3: -1 | T3: 2 | U3: =R3-T3 -> -3 | V3: =IF(R3=T3,1,0) -> 0 | W3: =IF(R3>T3,1,0) -> 0 | X3: =IF(R3<T3,1,0) -> 1 | Y3: =IF(R3=T3,"Agreement",IF(R3>T3,"Overestimation","Underestimation")) -> Underestimation | Z3: =S3-T3 -> -3 | AA3: =IF(S3=T3,1,0) -> 0 | AB3: =IF(S3>T3,1,0) -> 0 | AC3: =IF(S3<T3,1,0) -> 1 | AD3: =IF(S3=T3,"Agreement",IF(S3>T3,"Overestimation","Underestimation")) -> Underestimation | AE3: 0 | AF3: 1 | AG3: 1 | AH3: =AE3-AG3 -> -1 | AI3: =IF(AE3=AG3,1,0) -> 0 | AJ3: =IF(AE3>AG3,1,0) -> 0 | AK3: =IF(AE3<AG3,1,0) -> 1 | AL3: =IF(AE3=AG3,"Agreement",IF(AE3>AG3,"Overestimation","Underestimation")) -> Underestimation | AM3: =AF3-AG3 -> 0 | AN3: =IF(AF3=AG3,1,0) -> 1 | AO3: =IF(AF3>AG3,1,0) -> 0 | AP3: =IF(AF3<AG3,1,0) -> 0 | AQ3: =IF(AF3=AG3,"Agreement",IF(AF3>AG3,"Overestimation","Underestimation")) -> Agreement | AR3: the case does not provide any infomation on therapy start and end date or on the event date, thus temporal and biological plausability can not be established. | AS3: the case does not provide any infomation on therapy start and end date or on the event date, thus temporal and biological plausability can not be established. | AT3: the case does not provide any infomation on therapy start and end date or on the event date, thus temporal and biological plausability can not be established. | AU3: ## Pair Assessment: REGLAN vs Intentional product use issue **CrewAI Final Output:** ``` **Comprehensive Causality Assessment for Intentional product use issue Associated with REGLAN** **FINAL PLAUSIBILITY RATING:** LOW **Detailed Causality Analysis:** 1. **Temporal Plausibility** The assessment of a temporal relationship is impossible due to a complete lack of date information. The 'Event Date', 'Therapy Start' date, and 'Therapy End' date for REGLAN are all reported as 'MISSING'. Without these critical data points, it cannot be determined if the administration of REGLAN preceded the onset of the 'Intentional product use issue'. Therefore, temporal plausibility is **unassessable**. 2. **Biological Plausibility** The adverse event term 'Intentional product use issue' is non-specific but can be interpreted as an overdose or misuse scenario. The provided literature summary, based on established medical knowledge, confirms that REGLAN (metoclopramide) is a dopamine D2 receptor antagonist with significant central nervous system (CNS) effects. Overdose is known to cause CNS disturbances such as drowsiness, confusion, agitation, anxiety, and extrapyramidal symptoms (EPS), including akathisia. A state of drug-induced agitation or confusion could potentially lead to behavior classified as an 'intentional product use issue'. Thus, a biological mechanism for REGLAN to cause or contribute to such an event exists. The literature search for the specific event term yielded no results (PMIDs: Not Applicable). Biological plausibility is considered **plausible**. 3. **Dechallenge/Rechallenge** The effect of drug withdrawal (dechallenge) or re-administration (rechallenge) provides strong evidence for causality. In this case, the 'Dechallenge Result' for REGLAN is 'MISSING', and the 'Rechallenge Result' is 'MISSING'. Consequently, no conclusion can be drawn from this criterion. This aspect of the assessment is **unassessable**. 4. **Objective Evidence** There is no objective evidence provided in the case file (e.g., clinical observations, lab values, diagnostic reports) to substantiate the event. The patient (a 68-year-old female) has a reported 'History of Similar Reactions: Y', which could support a causal link; however, no details about the previous reaction(s) or associated drug(s) are provided, limiting the value of this information. The literature search for the specific event term was negative. 5. **Confounding Factors** Several significant confounding factors are present that could provide an alternative explanation for the event: * **Patient's Medical History:** The patient has a documented indication of 'Anxiety', which is a significant psychiatric comorbidity that could independently contribute to the reported event. * **Concurrent Medications:** The patient was taking PREDNISONE and DELTASONE for 'Anxiety'. Corticosteroids are well-documented to cause a wide range of psychiatric side effects, including agitation, mood disturbances, confusion, and psychosis, which could directly cause or contribute to an 'intentional product use issue'. * **Underlying Disease:** The patient's diagnosis of 'Immune thrombocytopenia' can be a source of significant psychological distress. * **Other Medications:** The patient was also started on DIAZEPAM, a benzodiazepine, which could have been used to treat the event (e.g., akathisia or agitation) or for the underlying anxiety, further complicating the clinical picture. 6. **Synthesis and Final Assessment** This case is severely limited by a lack of critical information, most notably the absence of any dates to establish a temporal sequence and the lack of dechallenge/rechallenge results. While there is a plausible biological mechanism by which a REGLAN overdose could lead to CNS effects manifesting as an 'intentional product use issue', this is purely theoretical in the context of this case. The presence of strong confounding factors, particularly the patient's pre-existing anxiety and concurrent use of corticosteroids (PREDNISONE/DELTASONE), provides a compelling alternative explanation for the event. Given the unassessable temporality and the strong likelihood of alternative causality, a direct causal relationship between REGLAN and the 'Intentional product use issue' is weakly supported. Therefore, the final causality rating is **LOW**. ``` | AV3: ## Pair Assessment: REGLAN vs Intentional product use issue **CrewAI Final Output:** ``` **Comprehensive Causality Assessment for Intentional product use issue Associated with REGLAN** **FINAL PLAUSIBILITY RATING:** LOW **Detailed Causality Analysis:** 1. **Temporal Plausibility** The assessment of a temporal relationship is impossible due to a complete lack of date information. The 'Event Date', 'Therapy Start' date, and 'Therapy End' date for REGLAN are all reported as 'MISSING'. Without these critical data points, it cannot be determined if the administration of REGLAN preceded the onset of the 'Intentional product use issue'. Therefore, temporal plausibility is **unassessable**. 2. **Biological Plausibility** The adverse event term 'Intentional product use issue' is non-specific but can be interpreted as an overdose or misuse scenario. The provided literature summary, based on established medical knowledge, confirms that REGLAN (metoclopramide) is a dopamine D2 receptor antagonist with significant central nervous system (CNS) effects. Overdose is known to cause CNS disturbances such as drowsiness, confusion, agitation, anxiety, and extrapyramidal symptoms (EPS), including akathisia. A state of drug-induced agitation or confusion could potentially lead to behavior classified as an 'intentional product use issue'. Thus, a biological mechanism for REGLAN to cause or contribute to such an event exists. The literature search for the specific event term yielded no results (PMIDs: Not Applicable). Biological plausibility is considered **plausible**. 3. **Dechallenge/Rechallenge** The effect of drug withdrawal (dechallenge) or re-administration (rechallenge) provides strong evidence for causality. In this case, the 'Dechallenge Result' for REGLAN is 'MISSING', and the 'Rechallenge Result' is 'MISSING'. Consequently, no conclusion can be drawn from this criterion. This aspect of the assessment is **unassessable**. 4. **Objective Evidence** There is no objective evidence provided in the case file (e.g., clinical observations, lab values, diagnostic reports) to substantiate the event. The patient (a 68-year-old female) has a reported 'History of Similar Reactions: Y', which could support a causal link; however, no details about the previous reaction(s) or associated drug(s) are provided, limiting the value of this information. The literature search for the specific event term was negative. 5. **Confounding Factors** Several significant confounding factors are present that could provide an alternative explanation for the event: * **Patient's Medical History:** The patient has a documented indication of 'Anxiety', which is a significant psychiatric comorbidity that could independently contribute to the reported event. * **Concurrent Medications:** The patient was taking PREDNISONE and DELTASONE for 'Anxiety'. Corticosteroids are well-documented to cause a wide range of psychiatric side effects, including agitation, mood disturbances, confusion, and psychosis, which could directly cause or contribute to an 'intentional product use issue'. * **Underlying Disease:** The patient's diagnosis of 'Immune thrombocytopenia' can be a source of significant psychological distress. * **Other Medications:** The patient was also started on DIAZEPAM, a benzodiazepine, which could have been used to treat the event (e.g., akathisia or agitation) or for the underlying anxiety, further complicating the clinical picture. 6. **Synthesis and Final Assessment** This case is severely limited by a lack of critical information, most notably the absence of any dates to establish a temporal sequence and the lack of dechallenge/rechallenge results. While there is a plausible biological mechanism by which a REGLAN overdose could lead to CNS effects manifesting as an 'intentional product use issue', this is purely theoretical in the context of this case. The presence of strong confounding factors, particularly the patient's pre-existing anxiety and concurrent use of corticosteroids (PREDNISONE/DELTASONE), provides a compelling alternative explanation for the event. Given the unassessable temporality and the strong likelihood of alternative causality, a direct causal relationship between REGLAN and the 'Intentional product use issue' is weakly supported. Therefore, the final causality rating is **LOW**. ``` | AW3: These are not pharmacological adverse reactions but usage/process issues. | AX3: Intentional product use issue: Symptom - Intentional product use issue refers to a patient's deliberate misuse or incorrect use of a product, which is a subjective behavior or action reported by the patient or caregiver, not an objective, measurable clinical finding. | AY3: Intentional product use issue: Sign - Intentional product use issue is an observable behavior or event, not a subjective patient-reported experience. | AZ3: since the intentional use is a clinical sign (as opposed to a symptom), it is assumed that the appropriate medical tests have been performed by a healthcare professional, prior to diagnosing. | BA3: Case ID: 153433253 Case Version: 3 FDA Code: F Event Date: NA Manufacture Date: 20180827 Initial FDA Date: 20180903 FDA Date: 20250430 Report Code: EXP Authorization Number: NA Manufacturer Number: US-ROCHE-2176536 Manufacturer Sender: ROCHE Literature Reference: NA Age: 68 Age Code: YR Age Group: E Sex: F E Sub: Y Weight: 71.73 Weight Code: KG Report Date: 20250430 To Manufacturer: NA Occupation Code: HP Reporter Country: US Occurrence Country: US Adverse Reaction(s): Aortic arteriosclerosis ; Dizziness ; Acute kidney injury ; Intentional product use issue ; Sepsis ; Nausea ; Hallucination ; Hypovolaemia ; Immunosuppression ; Atelectasis ; Serum sickness ; Spinal osteoarthritis ; Renal cyst ; Pyrexia ; Lactic acidosis ; Asthenia ; Off label use ; Pleural effusion ; Dehydration Case ID Number: 15343325 Drug Sequence: 6 ; 3 ; 4 ; 10 ; 7 ; 1 ; 9 ; 5 ; 2 ; 8 Role Code: C ; C ; C ; C ; C ; PS ; C ; C ; SS ; C Drug Name: THYROID ; NEXIUM ; PREDNISONE ; DELTASONE ; BENADRYL ; RITUXAN ; ZOFRAN ; PREDNISONE ; DIAZEPAM ; REGLAN Product AI: THYROID ; NEXIUM ; PREDNISONE ; DELTASONE ; BENADRYL ; RITUXAN ; ZOFRAN ; PREDNISONE ; DIAZEPAM ; REGLAN Val VBM: 1 ; 1 ; 1 ; 1 ; 1 ; 1 ; 1 ; 1 ; 1 ; 1 Route: Oral ; NA ; Oral ; NA ; NA ; Intravenous (not otherwise specified) ; NA ; Oral ; Unknown ; NA Dose VBM: daily ; daily ; 2.5 m/d daily ; 1mg daily or more 90 mg daily ; NA ; NA ; prn ; NA ; NA ; prn Cumulative Dose (Char): NA ; NA ; NA ; NA ; NA ; NA ; NA ; NA ; NA ; NA Cumulative Dose (Unit): NA ; NA ; NA ; NA ; NA ; NA ; NA ; NA ; NA ; NA Dechal: NA ; NA ; NA ; NA ; NA ; U ; NA ; NA ; U ; NA Rechal: NA ; NA ; NA ; NA ; NA ; NA ; NA ; NA ; NA ; NA Lot Number: NA ; NA ; NA ; NA ; NA ; Unknown ; NA ; NA ; Unknown ; NA Expiration Date: NA ; NA ; NA ; NA ; NA ; NA ; NA ; NA ; NA ; NA NDA Number: NA ; NA ; NA ; NA ; NA ; 103705 ; NA ; NA ; NA ; NA Dose Amount: 90 ; 20 ; NA ; NA ; NA ; 690 ; NA ; 1 ; 2 ; 10 Dose Unit: MG ; MG ; NA ; NA ; NA ; MG ; NA ; MG ; MG ; MG Dose Form: NA ; NA ; Tablet ; NA ; NA ; Solution for infusion ; NA ; 10 mg tablet ; NA ; NA Dose Frequency: QD ; QD ; QD ; NA ; NA ; /WK ; NA ; QOD ; NA ; Q6H Indication for Use: Immune thrombocytopenia ; Immune thrombocytopenia ; Anxiety ; Anxiety ; Gastrooesophageal reflux disease ; Immune thrombocytopenia ; Immune thrombocytopenia ; ; ; ; ; ; Therapy Start Date: NA ; NA ; NA ; NA ; NA ; 20180501 ; NA ; NA ; 20180522 ; NA Therapy End Date: NA ; NA ; 20180522 ; NA ; NA ; 20180508 ; NA ; NA ; NA ; NA Duration: NA ; NA ; NA ; NA ; NA ; 8 ; NA ; NA ; NA ; NA Duration Code: NA ; NA ; NA ; NA ; NA ; DAY ; NA ; NA ; NA ; NA
A4: 3 | B4: 180595396 | C4: Visual impairment | D4: XELJANZ | E4: 0 | F4: 0 | G4: 0 | H4: =E4-G4 -> 0 | I4: =IF(E4=G4,1,0) -> 1 | J4: =IF(E4>G4,1,0) -> 0 | K4: =IF(E4<G4,1,0) -> 0 | L4: =IF(E4=G4,"Agreement",IF(E4>G4,"Overestimation","Underestimation")) -> Agreement | M4: =F4-G4 -> 0 | N4: =IF(F4=G4,1,0) -> 1 | O4: =IF(F4>G4,1,0) -> 0 | P4: =IF(F4<G4,1,0) -> 0 | Q4: =IF(F4=G4,"Agreement",IF(F4>G4,"Overestimation","Underestimation")) -> Agreement | R4: -1 | S4: -1 | T4: -1 | U4: =R4-T4 -> 0 | V4: =IF(R4=T4,1,0) -> 1 | W4: =IF(R4>T4,1,0) -> 0 | X4: =IF(R4<T4,1,0) -> 0 | Y4: =IF(R4=T4,"Agreement",IF(R4>T4,"Overestimation","Underestimation")) -> Agreement | Z4: =S4-T4 -> 0 | AA4: =IF(S4=T4,1,0) -> 1 | AB4: =IF(S4>T4,1,0) -> 0 | AC4: =IF(S4<T4,1,0) -> 0 | AD4: =IF(S4=T4,"Agreement",IF(S4>T4,"Overestimation","Underestimation")) -> Agreement | AE4: 0 | AF4: 1 | AG4: 1 | AH4: =AE4-AG4 -> -1 | AI4: =IF(AE4=AG4,1,0) -> 0 | AJ4: =IF(AE4>AG4,1,0) -> 0 | AK4: =IF(AE4<AG4,1,0) -> 1 | AL4: =IF(AE4=AG4,"Agreement",IF(AE4>AG4,"Overestimation","Underestimation")) -> Underestimation | AM4: =AF4-AG4 -> 0 | AN4: =IF(AF4=AG4,1,0) -> 1 | AO4: =IF(AF4>AG4,1,0) -> 0 | AP4: =IF(AF4<AG4,1,0) -> 0 | AQ4: =IF(AF4=AG4,"Agreement",IF(AF4>AG4,"Overestimation","Underestimation")) -> Agreement | AR4: the case does not provide any infomation on therapy start and end date or on the event date, thus temporal and biological plausability can not be established. | AS4: the case does not provide any infomation on therapy start and end date or on the event date, thus temporal and biological plausability can not be established. | AT4: the case does not provide any infomation on therapy start and end date or on the event date, thus temporal and biological plausability can not be established. | AU4: ## Pair Assessment: XELJANZ vs Visual impairment **CrewAI Final Output:** ``` **Comprehensive Causality Assessment for Visual impairment Associated with XELJANZ** **FINAL PLAUSIBILITY RATING:** LOW **Detailed Causality Analysis:** 1. **Temporal Plausibility** The temporal relationship between the administration of XELJANZ and the onset of 'Visual impairment' cannot be assessed. Key data points, including the 'Therapy Start' date and the 'Event Date', are marked as 'MISSING' in the case metadata. Without this information, it is impossible to establish a reasonable time-to-onset or determine if the event occurred after the drug was initiated. This represents a significant weakness in the case for causality. 2. **Biological Plausibility** Based on the provided context, there is no information to support the biological plausibility of XELJANZ causing visual impairment. The literature summary, referencing a single article (PMID: 39976227), explicitly states that the article is a review of TNF inhibitors and contains "no clinical evidence, efficacy data, or safety data" regarding XELJANZ. Furthermore, the article does not mention "visual impairment" or related ocular events. Therefore, no known mechanism or clinical evidence from the provided materials links the drug to the event. 3. **Dechallenge/Rechallenge** The evidence from dechallenge and rechallenge does not support a causal association. The 'Dechallenge Result' is 'U' (Unknown), indicating that it is not known whether the patient's visual impairment improved or resolved after the drug was potentially stopped. The 'Rechallenge Result' is 'MISSING', meaning the patient was not re-exposed to the drug, or if they were, the outcome was not reported. This lack of positive dechallenge or rechallenge data fails to strengthen the case for causality. 4. **Objective Evidence** There is no objective evidence provided to support the diagnosis or the causal link. The report consists of the event term 'Visual impairment' without any accompanying clinical details, diagnostic test results (e.g., ophthalmologic exam findings, visual acuity measurements), or medical confirmation. The information is limited to a subjective report. 5. **Confounding Factors** Several significant confounding factors exist that provide strong alternative explanations for the event: * **Patient Age:** The patient is 70 years old, an age at which the incidence of various conditions causing visual impairment (e.g., cataracts, age-related macular degeneration, glaucoma) is high. * **Underlying Indication:** The patient was taking XELJANZ for 'Arthritis'. Certain types of inflammatory arthritis can have extra-articular manifestations, including ocular inflammation (e.g., uveitis, scleritis) that can lead to visual impairment. * **History of Similar Reactions:** The case metadata explicitly states 'History of Similar Reactions: Y'. This is a critical factor suggesting the patient has experienced similar episodes previously, which points towards a pre-existing or recurrent condition independent of XELJANZ therapy. * **Concurrent Medications:** While no concurrent medications were listed, the underlying disease and patient demographics are strong confounders. 6. **Synthesis and Final Assessment** The overall assessment indicates that a causal relationship between XELJANZ and 'Visual impairment' is unlikely. There is a complete lack of evidence supporting causality: the temporal relationship is unknown, no biological plausibility is provided in the supplied literature (PMID: 39976227), and the dechallenge/rechallenge results are uninformative. Conversely, there are compelling alternative explanations, including the patient's advanced age (70), the underlying 'Arthritis', and most significantly, a documented history of similar reactions. These factors strongly suggest an alternative etiology for the reported event. Therefore, the causality is rated as **LOW**. ``` | AV4: ## Pair Assessment: XELJANZ vs Visual impairment **CrewAI Final Output:** ``` **Comprehensive Causality Assessment for Visual impairment Associated with XELJANZ** **FINAL PLAUSIBILITY RATING:** LOW **Detailed Causality Analysis:** 1. **Temporal Plausibility** The temporal relationship between the administration of XELJANZ and the onset of 'Visual impairment' cannot be assessed. Key data points, including the 'Therapy Start' date and the 'Event Date', are marked as 'MISSING' in the case metadata. Without this information, it is impossible to establish a reasonable time-to-onset or determine if the event occurred after the drug was initiated. This represents a significant weakness in the case for causality. 2. **Biological Plausibility** Based on the provided context, there is no information to support the biological plausibility of XELJANZ causing visual impairment. The literature summary, referencing a single article (PMID: 39976227), explicitly states that the article is a review of TNF inhibitors and contains "no clinical evidence, efficacy data, or safety data" regarding XELJANZ. Furthermore, the article does not mention "visual impairment" or related ocular events. Therefore, no known mechanism or clinical evidence from the provided materials links the drug to the event. 3. **Dechallenge/Rechallenge** The evidence from dechallenge and rechallenge does not support a causal association. The 'Dechallenge Result' is 'U' (Unknown), indicating that it is not known whether the patient's visual impairment improved or resolved after the drug was potentially stopped. The 'Rechallenge Result' is 'MISSING', meaning the patient was not re-exposed to the drug, or if they were, the outcome was not reported. This lack of positive dechallenge or rechallenge data fails to strengthen the case for causality. 4. **Objective Evidence** There is no objective evidence provided to support the diagnosis or the causal link. The report consists of the event term 'Visual impairment' without any accompanying clinical details, diagnostic test results (e.g., ophthalmologic exam findings, visual acuity measurements), or medical confirmation. The information is limited to a subjective report. 5. **Confounding Factors** Several significant confounding factors exist that provide strong alternative explanations for the event: * **Patient Age:** The patient is 70 years old, an age at which the incidence of various conditions causing visual impairment (e.g., cataracts, age-related macular degeneration, glaucoma) is high. * **Underlying Indication:** The patient was taking XELJANZ for 'Arthritis'. Certain types of inflammatory arthritis can have extra-articular manifestations, including ocular inflammation (e.g., uveitis, scleritis) that can lead to visual impairment. * **History of Similar Reactions:** The case metadata explicitly states 'History of Similar Reactions: Y'. This is a critical factor suggesting the patient has experienced similar episodes previously, which points towards a pre-existing or recurrent condition independent of XELJANZ therapy. * **Concurrent Medications:** While no concurrent medications were listed, the underlying disease and patient demographics are strong confounders. 6. **Synthesis and Final Assessment** The overall assessment indicates that a causal relationship between XELJANZ and 'Visual impairment' is unlikely. There is a complete lack of evidence supporting causality: the temporal relationship is unknown, no biological plausibility is provided in the supplied literature (PMID: 39976227), and the dechallenge/rechallenge results are uninformative. Conversely, there are compelling alternative explanations, including the patient's advanced age (70), the underlying 'Arthritis', and most significantly, a documented history of similar reactions. These factors strongly suggest an alternative etiology for the reported event. Therefore, the causality is rated as **LOW**. ``` | AW4: Cataract, keratoconus, and other reported eye disorders represent plausible alternative explanations for visual impairment. | AX4: Visual impairment: Symptom - Visual impairment is a subjective experience reported by the patient regarding reduced vision quality, not directly observable or measurable without patient reporting. | AY4: Visual impairment: Sign - Visual impairment can be objectively measured through visual acuity tests or other assessments, making it a sign. | AZ4: since the intentional use is a clinical sign (as opposed to a symptom), it is assumed that the appropriate medical tests have been performed by a healthcare professional, prior to diagnosing. | BA4: Case ID: 180595396 Case Version: 6 FDA Code: F Event Date: NA Manufacture Date: 20250417 Initial FDA Date: 20200723 FDA Date: 20250424 Report Code: EXP Authorization Number: NA Manufacturer Number: US-PFIZER INC-2020280505 Manufacturer Sender: PFIZER Literature Reference: NA Age: 70 Age Code: YR Age Group: NA Sex: F E Sub: Y Weight: 69.85 Weight Code: KG Report Date: 20250424 To Manufacturer: NA Occupation Code: CN Reporter Country: US Occurrence Country: US Adverse Reaction(s): Visual impairment ; Cataract ; Drug dispensed to wrong patient ; Eye disorder ; Keratoconus Case ID Number: 18059539 Drug Sequence: 2 ; 1 Role Code: SS ; PS Drug Name: XELJANZ ; XELJANZ Product AI: XELJANZ ; XELJANZ Val VBM: 1 ; 1 Route: NA ; Oral Dose VBM: NA ; morning/evening Cumulative Dose (Char): NA ; NA Cumulative Dose (Unit): NA ; NA Dechal: U ; U Rechal: NA ; NA Lot Number: NA ; NA Expiration Date: NA ; NA NDA Number: 203214 ; 203214 Dose Amount: NA ; 5 Dose Unit: NA ; MG Dose Form: Tablet ; Tablet Dose Frequency: NA ; BID Indication for Use: Rheumatoid arthritis ; Arthritis Therapy Start Date: NA ; NA Therapy End Date: NA ; NA Duration: NA ; NA Duration Code: NA ; NA "
A5: 4 | B5: 194885198 | C5: General physical health deterioration | D5: AVASTIN | E5: 0 | F5: 0 | G5: 0 | H5: =E5-G5 -> 0 | I5: =IF(E5=G5,1,0) -> 1 | J5: =IF(E5>G5,1,0) -> 0 | K5: =IF(E5<G5,1,0) -> 0 | L5: =IF(E5=G5,"Agreement",IF(E5>G5,"Overestimation","Underestimation")) -> Agreement | M5: =F5-G5 -> 0 | N5: =IF(F5=G5,1,0) -> 1 | O5: =IF(F5>G5,1,0) -> 0 | P5: =IF(F5<G5,1,0) -> 0 | Q5: =IF(F5=G5,"Agreement",IF(F5>G5,"Overestimation","Underestimation")) -> Agreement | R5: -1 | S5: -1 | T5: -1 | U5: =R5-T5 -> 0 | V5: =IF(R5=T5,1,0) -> 1 | W5: =IF(R5>T5,1,0) -> 0 | X5: =IF(R5<T5,1,0) -> 0 | Y5: =IF(R5=T5,"Agreement",IF(R5>T5,"Overestimation","Underestimation")) -> Agreement | Z5: =S5-T5 -> 0 | AA5: =IF(S5=T5,1,0) -> 1 | AB5: =IF(S5>T5,1,0) -> 0 | AC5: =IF(S5<T5,1,0) -> 0 | AD5: =IF(S5=T5,"Agreement",IF(S5>T5,"Overestimation","Underestimation")) -> Agreement | AE5: 0 | AF5: 1 | AG5: 1 | AH5: =AE5-AG5 -> -1 | AI5: =IF(AE5=AG5,1,0) -> 0 | AJ5: =IF(AE5>AG5,1,0) -> 0 | AK5: =IF(AE5<AG5,1,0) -> 1 | AL5: =IF(AE5=AG5,"Agreement",IF(AE5>AG5,"Overestimation","Underestimation")) -> Underestimation | AM5: =AF5-AG5 -> 0 | AN5: =IF(AF5=AG5,1,0) -> 1 | AO5: =IF(AF5>AG5,1,0) -> 0 | AP5: =IF(AF5<AG5,1,0) -> 0 | AQ5: =IF(AF5=AG5,"Agreement",IF(AF5>AG5,"Overestimation","Underestimation")) -> Agreement | AR5: the case does not provide any infomation on therapy start and end date or on the event date, thus temporal and biological plausability can not be established. | AS5: the case does not provide any infomation on therapy start and end date or on the event date, thus temporal and biological plausability can not be established. | AT5: the case does not provide any infomation on therapy start and end date or on the event date, thus temporal and biological plausability can not be established. | AU5: ## Pair Assessment: AVASTIN vs General physical health deterioration **CrewAI Final Output:** ``` **Comprehensive Causality Assessment for General physical health deterioration Associated with AVASTIN** **FINAL PLAUSIBILITY RATING:** LOW **Detailed Causality Analysis:** 1. **Temporal Plausibility** The temporal relationship between the initiation of AVASTIN and the onset of the event is weak. The patient began therapy on 20160812 and the event of 'General physical health deterioration' was reported on 20210222, representing a latency period of approximately 4.5 years. While some adverse events can manifest after long-term treatment, this extended duration makes a direct, acute drug-induced event less likely. It is more suggestive of a gradual process, such as the progression of the underlying disease. 2. **Biological Plausibility** The provided context does not contain information on the mechanism of action (MOA) of AVASTIN (bevacizumab). 'General physical health deterioration' is a non-specific clinical sign that can result from numerous factors, most notably the progression of the patient's underlying rectal cancer. Without a described mechanism linking AVASTIN to such a non-specific, late-onset event, biological plausibility cannot be established from the available information. The event is more plausibly explained by cancer-related cachexia or disease progression. 3. **Dechallenge/Rechallenge** * **Dechallenge Result:** MISSING. It is unknown if AVASTIN was discontinued or the dose was reduced, and what effect this had on the patient's condition. * **Rechallenge Result:** MISSING. It is unknown if the patient was re-exposed to AVASTIN. The absence of dechallenge and rechallenge information is a significant limitation in this assessment, as it prevents observation of the event's response to drug withdrawal or reintroduction. 4. **Objective Evidence** The provided literature summary (PMID: 34295666) offers limited support. The study, a retrospective analysis of the FAERS database, found that AVASTIN in *combination* with a PD-(L)1 inhibitor was associated with a "significantly higher risk" of 'General physical health deterioration' compared to PD-(L)1 inhibitor monotherapy. However, this evidence is weakened by several factors: * The current case involves AVASTIN as a single agent, whereas the study assessed it in combination therapy. * The study population had non-small cell lung cancer (NSCLC), not rectal cancer. * The multivariate analysis within the study did not identify the combination therapy as an independent risk factor for 'General physical health deterioration', reducing the strength of the association. Therefore, the literature provides only a weak, indirect signal that does not directly apply to this case of monotherapy. 5. **Confounding Factors** There are significant confounding factors present: * **Underlying Disease:** The patient's indication for AVASTIN is rectal cancer. General physical health deterioration is a well-established and common manifestation of advanced or progressive malignancy. This represents a strong and highly plausible alternative cause for the reported event. * **History of Similar Reactions:** The case notes a "History of Similar Reactions: Y". Without details, this information is ambiguous. It could suggest a recurring drug sensitivity, but it is equally, if not more, likely to represent prior episodes of deterioration related to the underlying cancer. * **Concurrent Medications:** While listed as N/A, eliminating other drugs as confounders, the underlying disease itself is the most critical confounding factor. 6. **Synthesis and Final Assessment** The overall causality assessment is **LOW**. This conclusion is based on a weak temporal relationship given the 4.5-year latency, the absence of a described biological mechanism, and the complete lack of dechallenge/rechallenge data. The supporting literature (PMID: 34295666) is indirect and of limited applicability, as it pertains to combination therapy in a different patient population. Most importantly, a highly plausible and strong alternative explanation exists: the progression of the patient's underlying rectal cancer. The reported event is a characteristic feature of the natural history of this disease, especially after several years. The available evidence is insufficient to suggest that AVASTIN is a more likely cause than the disease itself. ``` | AV5: ## Pair Assessment: AVASTIN vs General physical health deterioration **CrewAI Final Output:** ``` **Comprehensive Causality Assessment for General physical health deterioration Associated with AVASTIN** **FINAL PLAUSIBILITY RATING:** LOW **Detailed Causality Analysis:** 1. **Temporal Plausibility** The temporal relationship between the initiation of AVASTIN and the onset of the event is weak. The patient began therapy on 20160812 and the event of 'General physical health deterioration' was reported on 20210222, representing a latency period of approximately 4.5 years. While some adverse events can manifest after long-term treatment, this extended duration makes a direct, acute drug-induced event less likely. It is more suggestive of a gradual process, such as the progression of the underlying disease. 2. **Biological Plausibility** The provided context does not contain information on the mechanism of action (MOA) of AVASTIN (bevacizumab). 'General physical health deterioration' is a non-specific clinical sign that can result from numerous factors, most notably the progression of the patient's underlying rectal cancer. Without a described mechanism linking AVASTIN to such a non-specific, late-onset event, biological plausibility cannot be established from the available information. The event is more plausibly explained by cancer-related cachexia or disease progression. 3. **Dechallenge/Rechallenge** * **Dechallenge Result:** MISSING. It is unknown if AVASTIN was discontinued or the dose was reduced, and what effect this had on the patient's condition. * **Rechallenge Result:** MISSING. It is unknown if the patient was re-exposed to AVASTIN. The absence of dechallenge and rechallenge information is a significant limitation in this assessment, as it prevents observation of the event's response to drug withdrawal or reintroduction. 4. **Objective Evidence** The provided literature summary (PMID: 34295666) offers limited support. The study, a retrospective analysis of the FAERS database, found that AVASTIN in *combination* with a PD-(L)1 inhibitor was associated with a "significantly higher risk" of 'General physical health deterioration' compared to PD-(L)1 inhibitor monotherapy. However, this evidence is weakened by several factors: * The current case involves AVASTIN as a single agent, whereas the study assessed it in combination therapy. * The study population had non-small cell lung cancer (NSCLC), not rectal cancer. * The multivariate analysis within the study did not identify the combination therapy as an independent risk factor for 'General physical health deterioration', reducing the strength of the association. Therefore, the literature provides only a weak, indirect signal that does not directly apply to this case of monotherapy. 5. **Confounding Factors** There are significant confounding factors present: * **Underlying Disease:** The patient's indication for AVASTIN is rectal cancer. General physical health deterioration is a well-established and common manifestation of advanced or progressive malignancy. This represents a strong and highly plausible alternative cause for the reported event. * **History of Similar Reactions:** The case notes a "History of Similar Reactions: Y". Without details, this information is ambiguous. It could suggest a recurring drug sensitivity, but it is equally, if not more, likely to represent prior episodes of deterioration related to the underlying cancer. * **Concurrent Medications:** While listed as N/A, eliminating other drugs as confounders, the underlying disease itself is the most critical confounding factor. 6. **Synthesis and Final Assessment** The overall causality assessment is **LOW**. This conclusion is based on a weak temporal relationship given the 4.5-year latency, the absence of a described biological mechanism, and the complete lack of dechallenge/rechallenge data. The supporting literature (PMID: 34295666) is indirect and of limited applicability, as it pertains to combination therapy in a different patient population. Most importantly, a highly plausible and strong alternative explanation exists: the progression of the patient's underlying rectal cancer. The reported event is a characteristic feature of the natural history of this disease, especially after several years. The available evidence is insufficient to suggest that AVASTIN is a more likely cause than the disease itself. ``` | AW5: Underlying rectal cancer with metastatic disease and surgeries represents a plausible alternative explanation for health deterioration. | AX5: General physical health deterioration: Symptom - This term describes a subjective decline in overall health status that is typically reported by the patient rather than objectively measured or observed by a clinician. | AY5: General physical health deterioration: Sign - General physical health deterioration is an objective assessment of decline in health status, often based on observable clinical findings such as weight loss, decreased mobility, or lab abnormalities. | AZ5: since the intentional use is a clinical sign (as opposed to a symptom), it is assumed that the appropriate medical tests have been performed by a healthcare professional, prior to diagnosing. | BA5: Case ID: 194885198 Case Version: 8 FDA Code: F Event Date: 20210222 Manufacture Date: 20250227 Initial FDA Date: 20210702 FDA Date: 20250310 Report Code: EXP Authorization Number: NA Manufacturer Number: CN-ROCHE-2856623 Manufacturer Sender: ROCHE Literature Reference: NA Age: 52 Age Code: YR Age Group: A Sex: F E Sub: Y Weight: 54 Weight Code: KG Report Date: 20250310 To Manufacturer: NA Occupation Code: CN Reporter Country: CN Occurrence Country: CN Adverse Reaction(s): Pulmonary mass ; Lung neoplasm ; Lung operation ; Surgery ; Metastases to lung ; General physical health deterioration ; Hepatectomy Case ID Number: 19488519 Drug Sequence: 1 ; 2 Role Code: PS ; SS Drug Name: AVASTIN ; AVASTIN Product AI: AVASTIN ; AVASTIN Val VBM: 1 ; 1 Route: Intravenous (not otherwise specified) ; Intravenous (not otherwise specified) Dose VBM: NA ; NA Cumulative Dose (Char): NA ; NA Cumulative Dose (Unit): NA ; NA Dechal: NA ; NA Rechal: NA ; NA Lot Number: Asked But Unknown ; Asked But Unknown Expiration Date: NA ; NA NDA Number: 125085 ; 125085 Dose Amount: 300 ; 400 Dose Unit: MG ; MG Dose Form: Solution for infusion ; Solution for infusion Dose Frequency: QOW ; Q3W Indication for Use: Rectal cancer ; Rectal cancer ; ; Therapy Start Date: 20160812 ; 20170411 Therapy End Date: NA ; NA Duration: NA ; NA Duration Code: NA ; NA
